<sdf version='1.6'>
  <world name='default'>
    <light name='sun' type='directional'>
      <cast_shadows>1</cast_shadows>
      <pose frame=''>0 0 10 0 -0 0</pose>
      <diffuse>0.8 0.8 0.8 1</diffuse>
      <specular>0.2 0.2 0.2 1</specular>
      <attenuation>
        <range>1000</range>
        <constant>0.9</constant>
        <linear>0.01</linear>
        <quadratic>0.001</quadratic>
      </attenuation>
      <direction>-0.5 0.1 -0.9</direction>
    </light>
    <gravity>0 0 -9.8</gravity>
    <magnetic_field>6e-06 2.3e-05 -4.2e-05</magnetic_field>
    <atmosphere type='adiabatic'/>
    <physics name='default_physics' default='0' type='ode'>
      <max_step_size>0.001</max_step_size>
      <real_time_factor>1</real_time_factor>
      <real_time_update_rate>1000</real_time_update_rate>
    </physics>
    <scene>
      <ambient>0.4 0.4 0.4 1</ambient>
      <background>0.7 0.7 0.7 1</background>
      <shadows>1</shadows>
    </scene>
    <wind/>
    <spherical_coordinates>
      <surface_model>EARTH_WGS84</surface_model>
      <latitude_deg>0</latitude_deg>
      <longitude_deg>0</longitude_deg>
      <elevation>0</elevation>
      <heading_deg>0</heading_deg>
    </spherical_coordinates>
    <model name='sonoma_raceway'>
      <pose frame=''>0.415358 -0.673903 -4.8 0 -0 0</pose>
      <static>1</static>
      <link name='link'>
        <collision name='collision'>
          <geometry>
            <mesh>
              <uri>model://sonoma_raceway/meshes/Raceway.obj</uri>
              <scale>0.0254 0.0254 0.0254</scale>
            </mesh>
          </geometry>
          <max_contacts>10</max_contacts>
          <surface>
            <contact>
              <ode/>
            </contact>
            <bounce/>
            <friction>
              <torsional>
                <ode/>
              </torsional>
              <ode/>
            </friction>
          </surface>
        </collision>
        <visual name='visual'>
          <geometry>
            <mesh>
              <uri>model://sonoma_raceway/meshes/Raceway.obj</uri>
              <scale>0.0254 0.0254 0.0254</scale>
            </mesh>
          </geometry>
        </visual>
        <self_collide>0</self_collide>
        <enable_wind>0</enable_wind>
        <kinematic>0</kinematic>
      </link>
    </model>
    <state world_name='default'>
      <sim_time>782 959000000</sim_time>
      <real_time>3095 906887254</real_time>
      <wall_time>1590573535 417552055</wall_time>
      <iterations>224133</iterations>
      <model name='Construction Cone'>
        <pose frame=''>-11.8761 -1.92527 -0.148254 -1e-06 1e-06 0</pose>
        <scale>1 1 1</scale>
        <link name='link'>
          <pose frame=''>-11.8761 -1.92527 -0.148254 -1e-06 1e-06 0</pose>
          <velocity>0 -0 -0.009561 -0.000745 0.000443 -0</velocity>
          <acceleration>0 0 -9.8 0 -0 0</acceleration>
          <wrench>0 0 -9.8 0 -0 0</wrench>
        </link>
      </model>
      <model name='Construction Cone_0'>
        <pose frame=''>-11.4937 -2.48057 -0.148244 0 -0 0</pose>
        <scale>1 1 1</scale>
        <link name='link'>
          <pose frame=''>-11.4937 -2.48057 -0.148244 0 -0 0</pose>
          <velocity>-0 0 1e-06 1e-06 1e-06 0</velocity>
          <acceleration>-0 0 0.001565 0.003402 0.001818 -0</acceleration>
          <wrench>-0 0 0.001565 0 -0 0</wrench>
        </link>
      </model>
      <model name='Construction Cone_1'>
        <pose frame=''>-13.1213 22.9239 -0.148244 0 -0 0</pose>
        <scale>1 1 1</scale>
        <link name='link'>
          <pose frame=''>-13.1213 22.9239 -0.148244 0 -0 0</pose>
          <velocity>-0 -0 6.7e-05 0.000163 -0.000154 -0</velocity>
          <acceleration>0 -0 -9.6702 -0.032639 0.022089 -0</acceleration>
          <wrench>0 -0 -9.6702 0 -0 0</wrench>
        </link>
      </model>
      <model name='Construction Cone_10'>
        <pose frame=''>-26.5222 39.1001 -0.148244 0 -0 0</pose>
        <scale>1 1 1</scale>
        <link name='link'>
          <pose frame=''>-26.5222 39.1001 -0.148244 0 -0 0</pose>
          <velocity>0 -0 -0.000171 -0.000145 -0.000364 -0</velocity>
          <acceleration>0 0 -9.8 0 -0 0</acceleration>
          <wrench>0 0 -9.8 0 -0 0</wrench>
        </link>
      </model>
      <model name='Construction Cone_11'>
        <pose frame=''>-23.9286 58.4712 -0.148244 0 -0 0</pose>
        <scale>1 1 1</scale>
        <link name='link'>
          <pose frame=''>-23.9286 58.4712 -0.148244 0 -0 0</pose>
          <velocity>-0 0 -0 -0 -0 -0</velocity>
          <acceleration>-0 0 0 0 -0 0</acceleration>
          <wrench>-0 0 0 0 -0 0</wrench>
        </link>
      </model>
      <model name='Construction Cone_12'>
        <pose frame=''>-32.5189 56.987 -0.148244 0 -0 0</pose>
        <scale>1 1 1</scale>
        <link name='link'>
          <pose frame=''>-32.5189 56.987 -0.148244 0 -0 0</pose>
          <velocity>0 -0 0.008807 7.5e-05 0.0001 0</velocity>
          <acceleration>0 -0 17.6494 0.038056 0.019092 -0</acceleration>
          <wrench>0 -0 17.6494 0 -0 0</wrench>
        </link>
      </model>
      <model name='Construction Cone_13'>
        <pose frame=''>-27.5165 68.6698 -0.148244 0 -0 0</pose>
        <scale>1 1 1</scale>
        <link name='link'>
          <pose frame=''>-27.5165 68.6698 -0.148244 0 -0 0</pose>
          <velocity>-0 0 0 0 -0 0</velocity>
          <acceleration>0 -0 -0.001337 -0.000607 -0.002908 -0</acceleration>
          <wrench>0 -0 -0.001337 0 -0 0</wrench>
        </link>
      </model>
      <model name='Construction Cone_14'>
        <pose frame=''>-37.022 70.7723 -0.148244 0 -0 0</pose>
        <scale>1 1 1</scale>
        <link name='link'>
          <pose frame=''>-37.022 70.7723 -0.148244 0 -0 0</pose>
          <velocity>-0 0 -0 -0 -0 -0</velocity>
          <acceleration>-0 0 -0 0 -0 0</acceleration>
          <wrench>-0 0 -0 0 -0 0</wrench>
        </link>
      </model>
      <model name='Construction Cone_15'>
        <pose frame=''>-30.7685 74.8574 -0.148244 1e-06 -0 0</pose>
        <scale>1 1 1</scale>
        <link name='link'>
          <pose frame=''>-30.7685 74.8574 -0.148244 1e-06 -0 0</pose>
          <velocity>0 -0 0.000658 -0.000797 -0.000176 0</velocity>
          <acceleration>0 -1e-06 1.05605 -1.85709 0.338946 0</acceleration>
          <wrench>0 -1e-06 1.05605 0 -0 0</wrench>
        </link>
      </model>
      <model name='Construction Cone_16'>
        <pose frame=''>-43.3965 89.815 -0.148244 0 -0 0</pose>
        <scale>1 1 1</scale>
        <link name='link'>
          <pose frame=''>-43.3965 89.815 -0.148244 0 -0 0</pose>
          <velocity>0 -0 8.1e-05 -7.9e-05 -0.000222 0</velocity>
          <acceleration>-0 0 0.099509 -0.45624 -0.615639 0</acceleration>
          <wrench>-0 0 0.099509 0 -0 0</wrench>
        </link>
      </model>
      <model name='Construction Cone_2'>
        <pose frame=''>-14.4173 26.8144 -0.148244 0 -0 0</pose>
        <scale>1 1 1</scale>
        <link name='link'>
          <pose frame=''>-14.4173 26.8144 -0.148244 0 -0 0</pose>
          <velocity>-0 0 -0 -0 -0 -0</velocity>
          <acceleration>0 0 0 0 -0 0</acceleration>
          <wrench>0 0 0 0 -0 0</wrench>
        </link>
      </model>
      <model name='Construction Cone_3'>
        <pose frame=''>-16.8803 34.8919 -0.148244 1e-06 -0 0</pose>
        <scale>1 1 1</scale>
        <link name='link'>
          <pose frame=''>-16.8803 34.8919 -0.148244 1e-06 -0 0</pose>
          <velocity>-0 0 0.008353 0.000641 -0.001857 0</velocity>
          <acceleration>-1e-06 -1e-06 16.9143 -0.18726 -1.51034 2e-06</acceleration>
          <wrench>-1e-06 -1e-06 16.9143 0 -0 0</wrench>
        </link>
      </model>
      <model name='Construction Cone_4'>
        <pose frame=''>-15.4702 30.6217 -0.148244 0 -0 0</pose>
        <scale>1 1 1</scale>
        <link name='link'>
          <pose frame=''>-15.4702 30.6217 -0.148244 0 -0 0</pose>
          <velocity>-0 -0 0.000725 0.000217 -3e-05 0</velocity>
          <acceleration>-0 -0 1.4595 0.146114 -0.03186 0</acceleration>
          <wrench>-0 -0 1.4595 0 -0 0</wrench>
        </link>
      </model>
      <model name='Construction Cone_5'>
        <pose frame=''>-18.8748 40.8502 -0.148244 0 -0 0</pose>
        <scale>1 1 1</scale>
        <link name='link'>
          <pose frame=''>-18.8748 40.8502 -0.148244 0 -0 0</pose>
          <velocity>-0 0 -0 -0 -0 -0</velocity>
          <acceleration>-0 -0 -0 0 -0 0</acceleration>
          <wrench>-0 -0 -0 0 -0 0</wrench>
        </link>
      </model>
      <model name='Construction Cone_6'>
        <pose frame=''>-20.9265 21.2475 -0.148254 2e-06 -1e-06 -0</pose>
        <scale>1 1 1</scale>
        <link name='link'>
          <pose frame=''>-20.9265 21.2475 -0.148254 2e-06 -1e-06 -0</pose>
          <velocity>-0 -0 -0.00982 0.000699 -0.000605 0</velocity>
          <acceleration>0 0 -9.8 0 -0 0</acceleration>
          <wrench>0 0 -9.8 0 -0 0</wrench>
        </link>
      </model>
      <model name='Construction Cone_7'>
        <pose frame=''>-22.1856 24.8586 -0.148253 2e-06 -1e-06 -0</pose>
        <scale>1 1 1</scale>
        <link name='link'>
          <pose frame=''>-22.1856 24.8586 -0.148253 2e-06 -1e-06 -0</pose>
          <velocity>-0 -0 -0.009685 0.00085 -0.001244 0</velocity>
          <acceleration>0 0 -9.8 0 -0 0</acceleration>
          <wrench>0 0 -9.8 0 -0 0</wrench>
        </link>
      </model>
      <model name='Construction Cone_8'>
        <pose frame=''>-23.1731 28.9611 -0.148253 1e-06 -0 0</pose>
        <scale>1 1 1</scale>
        <link name='link'>
          <pose frame=''>-23.1731 28.9611 -0.148253 1e-06 -0 0</pose>
          <velocity>0 -0 -0.009307 -8.6e-05 -0.00014 0</velocity>
          <acceleration>0 0 -9.8 0 -0 0</acceleration>
          <wrench>0 0 -9.8 0 -0 0</wrench>
        </link>
      </model>
      <model name='Construction Cone_9'>
        <pose frame=''>-24.6237 33.1476 -0.148254 0 -0 0</pose>
        <scale>1 1 1</scale>
        <link name='link'>
          <pose frame=''>-24.6237 33.1476 -0.148254 0 -0 0</pose>
          <velocity>-0 0 -0.0098 0 -0 0</velocity>
          <acceleration>0 0 -9.8 0 -0 0</acceleration>
          <wrench>0 0 -9.8 0 -0 0</wrench>
        </link>
      </model>
      <model name='bookshelf'>
        <pose frame=''>-7.25855 -10.9127 0 0 -0 0</pose>
        <scale>1 1 1</scale>
        <link name='link'>
          <pose frame=''>-7.25855 -10.9127 0 0 -0 0</pose>
          <velocity>0 0 0 0 -0 0</velocity>
          <acceleration>0 0 0 0 -0 0</acceleration>
          <wrench>0 0 0 0 -0 0</wrench>
        </link>
      </model>
      <model name='cessna_c172'>
        <pose frame=''>-8.51973 13.9937 0.34384 -0.000179 -0.001141 0.130063</pose>
        <scale>1 1 1</scale>
        <link name='body'>
          <pose frame=''>-8.51973 13.9937 0.34384 -0.000179 -0.001141 0.130063</pose>
          <velocity>-0.009012 0.000817 0.00914 -0.004299 0.008911 -0.000236</velocity>
          <acceleration>0.053492 -0.393677 0.215856 -0.081638 0.254175 -0.066658</acceleration>
          <wrench>36.3953 -267.854 146.866 0 -0 0</wrench>
        </link>
        <link name='elevators'>
          <pose frame=''>-8.99236 13.9324 3.22728 -0.000208 -0.531156 0.130168</pose>
          <velocity>0.026062 0.01455 -0.007118 -0.004829 0.012959 -0.000237</velocity>
          <acceleration>-0.01407 -0.049618 1.54892 0.155855 -0.952959 -0.066423</acceleration>
          <wrench>-0.02814 -0.099236 3.09784 0 -0 0</wrench>
        </link>
        <link name='front_wheel'>
          <pose frame=''>-7.80677 14.0871 0.809505 -0.000755 1.16523 0.129373</pose>
          <velocity>-0.060731 -0.027599 0.001424 0.029262 -0.063447 0.000478</velocity>
          <acceleration>-0.19826 -0.693728 -3.22477 -2.22963 -0.93776 0.26444</acceleration>
          <wrench>-0.396519 -1.38746 -6.44955 0 -0 0</wrench>
        </link>
        <link name='left_aileron'>
          <pose frame=''>-8.10983 13.9412 1.47611 -0.062263 -0.52716 0.119752</pose>
          <velocity>0.000743 0.005781 0.001817 -0.004317 0.010619 -0.00015</velocity>
          <acceleration>0.451751 -0.2076 0.356264 -0.064365 0.314794 -0.064287</acceleration>
          <wrench>0.903501 -0.4152 0.712527 0 -0 0</wrench>
        </link>
        <link name='left_flap'>
          <pose frame=''>-8.03481 14.0371 1.345 0.002987 -0.53105 0.118442</pose>
          <velocity>-0.002693 0.004941 -0.009173 -0.005155 0.015451 -0.000105</velocity>
          <acceleration>0.408376 -0.200386 0.315163 -2.79207 -1.33664 3.03464</acceleration>
          <wrench>0.816753 -0.400772 0.630327 0 -0 0</wrench>
        </link>
        <link name='propeller'>
          <pose frame=''>-6.74583 14.2259 1.20088 -0.012934 -0.00114 0.130063</pose>
          <velocity>-0.00132 0.004228 -0.007668 -0.001437 0.009291 -0.000108</velocity>
          <acceleration>0.047943 -0.501606 -0.180891 -0.034885 0.264993 0.299551</acceleration>
          <wrench>0.880716 -9.21451 -3.32298 0 -0 0</wrench>
        </link>
        <link name='rear_left_wheel'>
          <pose frame=''>-9.42545 13.8769 1.13095 -0.005116 -1.24172 0.134907</pose>
          <velocity>-0.047492 0.002995 0.014513 -0.002264 -0.037512 0.000392</velocity>
          <acceleration>-0.255867 -0.311887 -0.127562 1.13838 -0.969279 0.013288</acceleration>
          <wrench>-0.511734 -0.623774 -0.255123 0 -0 0</wrench>
        </link>
        <link name='rear_right_wheel'>
          <pose frame=''>-8.50097 13.9959 0.260852 0.000758 0.090661 0.130149</pose>
          <velocity>-0.018603 -0.000435 0.04753 0.001017 -0.046599 -0.000319</velocity>
          <acceleration>-0.391283 -0.273248 -0.004133 -2.2226 -1.56165 2.96695</acceleration>
          <wrench>-0.782566 -0.546496 -0.008267 0 -0 0</wrench>
        </link>
        <link name='right_aileron'>
          <pose frame=''>-8.13716 14.1502 1.47608 0.061849 -0.527162 0.140582</pose>
          <velocity>0.000622 0.005077 -0.002515 -0.005111 0.012088 -0.000401</velocity>
          <acceleration>-0.000818 -0.262352 0.757353 0.299868 -0.988624 -0.001007</acceleration>
          <wrench>-0.001636 -0.524703 1.51471 0 -0 0</wrench>
        </link>
        <link name='right_flap'>
          <pose frame=''>-8.04 14.0768 1.34499 -0.003403 -0.531046 0.141893</pose>
          <velocity>-0.002629 0.004391 -0.009411 -0.005161 0.015498 -0.00037</velocity>
          <acceleration>0.205758 -0.238203 0.506609 -2.79003 -1.32583 3.11856</acceleration>
          <wrench>0.411516 -0.476406 1.01322 0 -0 0</wrench>
        </link>
        <link name='rudder'>
          <pose frame=''>-8.52057 14.0001 0.343837 -0.000616 -0.00114 0.131254</pose>
          <velocity>-0.026317 0.131909 0.009035 -0.013149 0.007758 0.024126</velocity>
          <acceleration>0.092532 0.065869 1.82973 -0.011509 0.274175 -0.288351</acceleration>
          <wrench>0.185065 0.131737 3.65946 0 -0 0</wrench>
        </link>
      </model>
      <model name='cinder_block'>
        <pose frame=''>-10.1759 -2.5943 -0.149205 0 -0 0</pose>
        <scale>1 1 1</scale>
        <link name='link'>
          <pose frame=''>-10.1759 -2.5943 -0.149205 0 -0 0</pose>
          <velocity>-0 0 0 0 -0 0</velocity>
          <acceleration>0 -0 -0 0 -0 0</acceleration>
          <wrench>0 -0 -0 0 -0 0</wrench>
        </link>
      </model>
      <model name='gazebo'>
        <pose frame=''>-8.95114 2.72054 0 0 -0 0</pose>
        <scale>1 1 1</scale>
        <link name='link'>
          <pose frame=''>-8.95114 2.72054 0 0 -0 0</pose>
          <velocity>0 0 0 0 -0 0</velocity>
          <acceleration>0 0 0 0 -0 0</acceleration>
          <wrench>0 0 0 0 -0 0</wrench>
        </link>
      </model>
      <model name='sonoma_raceway'>
        <pose frame=''>-459.228 430.08 -4.8 0 -0 0</pose>
        <scale>1 1 1</scale>
        <link name='link'>
          <pose frame=''>-459.228 430.08 -4.8 0 -0 0</pose>
          <velocity>0 0 0 0 -0 0</velocity>
          <acceleration>0 0 0 0 -0 0</acceleration>
          <wrench>0 0 0 0 -0 0</wrench>
        </link>
      </model>
      <light name='sun'>
        <pose frame=''>0 0 10 0 -0 0</pose>
      </light>
    </state>
    <gui fullscreen='0'>
      <camera name='user_camera'>
        <pose frame=''>-30.0557 49.7202 13.7913 0 0.541797 1.78019</pose>
        <view_controller>orbit</view_controller>
        <projection_type>perspective</projection_type>
      </camera>
    </gui>
    <model name='bookshelf'>
      <static>1</static>
      <link name='link'>
        <inertial>
          <mass>1</mass>
        </inertial>
        <collision name='back'>
          <pose frame=''>0 0.005 0.6 0 -0 0</pose>
          <geometry>
            <box>
              <size>0.9 0.01 1.2</size>
            </box>
          </geometry>
          <max_contacts>10</max_contacts>
          <surface>
            <contact>
              <ode/>
            </contact>
            <bounce/>
            <friction>
              <torsional>
                <ode/>
              </torsional>
              <ode/>
            </friction>
          </surface>
        </collision>
        <visual name='visual1'>
          <pose frame=''>0 0.005 0.6 0 -0 0</pose>
          <geometry>
            <box>
              <size>0.9 0.01 1.2</size>
            </box>
          </geometry>
          <material>
            <script>
              <uri>file://media/materials/scripts/gazebo.material</uri>
              <name>Gazebo/Wood</name>
            </script>
          </material>
        </visual>
        <collision name='left_side'>
          <pose frame=''>0.45 -0.195 0.6 0 -0 0</pose>
          <geometry>
            <box>
              <size>0.02 0.4 1.2</size>
            </box>
          </geometry>
          <max_contacts>10</max_contacts>
          <surface>
            <contact>
              <ode/>
            </contact>
            <bounce/>
            <friction>
              <torsional>
                <ode/>
              </torsional>
              <ode/>
            </friction>
          </surface>
        </collision>
        <visual name='visual2'>
          <pose frame=''>0.45 -0.195 0.6 0 -0 0</pose>
          <geometry>
            <box>
              <size>0.02 0.4 1.2</size>
            </box>
          </geometry>
          <material>
            <script>
              <uri>file://media/materials/scripts/gazebo.material</uri>
              <name>Gazebo/Wood</name>
            </script>
          </material>
        </visual>
        <collision name='right_side'>
          <pose frame=''>-0.45 -0.195 0.6 0 -0 0</pose>
          <geometry>
            <box>
              <size>0.02 0.4 1.2</size>
            </box>
          </geometry>
          <max_contacts>10</max_contacts>
          <surface>
            <contact>
              <ode/>
            </contact>
            <bounce/>
            <friction>
              <torsional>
                <ode/>
              </torsional>
              <ode/>
            </friction>
          </surface>
        </collision>
        <visual name='visual3'>
          <pose frame=''>-0.45 -0.195 0.6 0 -0 0</pose>
          <geometry>
            <box>
              <size>0.02 0.4 1.2</size>
            </box>
          </geometry>
          <material>
            <script>
              <uri>file://media/materials/scripts/gazebo.material</uri>
              <name>Gazebo/Wood</name>
            </script>
          </material>
        </visual>
        <collision name='bottom'>
          <pose frame=''>0 -0.195 0.03 0 -0 0</pose>
          <geometry>
            <box>
              <size>0.88 0.4 0.06</size>
            </box>
          </geometry>
          <max_contacts>10</max_contacts>
          <surface>
            <contact>
              <ode/>
            </contact>
            <bounce/>
            <friction>
              <torsional>
                <ode/>
              </torsional>
              <ode/>
            </friction>
          </surface>
        </collision>
        <visual name='visual4'>
          <pose frame=''>0 -0.195 0.03 0 -0 0</pose>
          <geometry>
            <box>
              <size>0.88 0.4 0.06</size>
            </box>
          </geometry>
          <material>
            <script>
              <uri>file://media/materials/scripts/gazebo.material</uri>
              <name>Gazebo/Wood</name>
            </script>
          </material>
        </visual>
        <collision name='top'>
          <pose frame=''>0 -0.195 1.19 0 -0 0</pose>
          <geometry>
            <box>
              <size>0.88 0.4 0.02</size>
            </box>
          </geometry>
          <max_contacts>10</max_contacts>
          <surface>
            <contact>
              <ode/>
            </contact>
            <bounce/>
            <friction>
              <torsional>
                <ode/>
              </torsional>
              <ode/>
            </friction>
          </surface>
        </collision>
        <visual name='visual5'>
          <pose frame=''>0 -0.195 1.19 0 -0 0</pose>
          <geometry>
            <box>
              <size>0.88 0.4 0.02</size>
            </box>
          </geometry>
          <material>
            <script>
              <uri>file://media/materials/scripts/gazebo.material</uri>
              <name>Gazebo/Wood</name>
            </script>
          </material>
        </visual>
        <collision name='low_shelf'>
          <pose frame=''>0 -0.195 0.43 0 -0 0</pose>
          <geometry>
            <box>
              <size>0.88 0.4 0.02</size>
            </box>
          </geometry>
          <max_contacts>10</max_contacts>
          <surface>
            <contact>
              <ode/>
            </contact>
            <bounce/>
            <friction>
              <torsional>
                <ode/>
              </torsional>
              <ode/>
            </friction>
          </surface>
        </collision>
        <visual name='visual6'>
          <pose frame=''>0 -0.195 0.43 0 -0 0</pose>
          <geometry>
            <box>
              <size>0.88 0.4 0.02</size>
            </box>
          </geometry>
          <material>
            <script>
              <uri>file://media/materials/scripts/gazebo.material</uri>
              <name>Gazebo/Wood</name>
            </script>
          </material>
        </visual>
        <collision name='high_shelf'>
          <pose frame=''>0 -0.195 0.8 0 -0 0</pose>
          <geometry>
            <box>
              <size>0.88 0.4 0.02</size>
            </box>
          </geometry>
          <max_contacts>10</max_contacts>
          <surface>
            <contact>
              <ode/>
            </contact>
            <bounce/>
            <friction>
              <torsional>
                <ode/>
              </torsional>
              <ode/>
            </friction>
          </surface>
        </collision>
        <visual name='visual7'>
          <pose frame=''>0 -0.195 0.8 0 -0 0</pose>
          <geometry>
            <box>
              <size>0.88 0.4 0.02</size>
            </box>
          </geometry>
          <material>
            <script>
              <uri>file://media/materials/scripts/gazebo.material</uri>
              <name>Gazebo/Wood</name>
            </script>
          </material>
        </visual>
        <self_collide>0</self_collide>
        <enable_wind>0</enable_wind>
        <kinematic>0</kinematic>
      </link>
      <pose frame=''>-7.25855 -10.9127 0 0 -0 0</pose>
    </model>
    <model name='cinder_block'>
      <link name='link'>
        <inertial>
          <pose frame=''>0 0 0.1016 0 -0 0</pose>
          <mass>5</mass>
          <inertia>
            <ixx>0.028705</ixx>
            <ixy>0</ixy>
            <iyy>0.073708</iyy>
            <ixz>0</ixz>
            <iyz>0</iyz>
            <izz>0.06908</izz>
          </inertia>
        </inertial>
        <visual name='visual'>
          <geometry>
            <mesh>
              <uri>model://cinder_block/meshes/cinder_block.dae</uri>
            </mesh>
          </geometry>
        </visual>
        <collision name='left'>
          <pose frame=''>0 -0.08465 0.1016 0 -0 0</pose>
          <geometry>
            <box>
              <size>0.43495 0.0339 0.2032</size>
            </box>
          </geometry>
          <surface>
            <contact>
              <ode>
                <max_vel>0.1</max_vel>
                <min_depth>0.001</min_depth>
              </ode>
            </contact>
            <friction>
              <ode>
                <mu>1</mu>
                <mu2>1</mu2>
              </ode>
              <torsional>
                <ode/>
              </torsional>
            </friction>
            <bounce/>
          </surface>
          <max_contacts>10</max_contacts>
        </collision>
        <collision name='right'>
          <pose frame=''>0 0.08465 0.1016 0 -0 0</pose>
          <geometry>
            <box>
              <size>0.43495 0.0339 0.2032</size>
            </box>
          </geometry>
          <surface>
            <contact>
              <ode>
                <max_vel>0.1</max_vel>
                <min_depth>0.001</min_depth>
              </ode>
            </contact>
            <friction>
              <ode>
                <mu>1</mu>
                <mu2>1</mu2>
              </ode>
              <torsional>
                <ode/>
              </torsional>
            </friction>
            <bounce/>
          </surface>
          <max_contacts>10</max_contacts>
        </collision>
        <collision name='front'>
          <pose frame=''>0.18625 0 0.1016 0 -0 0</pose>
          <geometry>
            <box>
              <size>0.0339 0.1354 0.203</size>
            </box>
          </geometry>
          <surface>
            <contact>
              <ode>
                <max_vel>0.1</max_vel>
                <min_depth>0.001</min_depth>
              </ode>
            </contact>
            <friction>
              <ode>
                <mu>1</mu>
                <mu2>1</mu2>
              </ode>
              <torsional>
                <ode/>
              </torsional>
            </friction>
            <bounce/>
          </surface>
          <max_contacts>10</max_contacts>
        </collision>
        <collision name='middle'>
          <pose frame=''>0 0 0.1016 0 -0 0</pose>
          <geometry>
            <box>
              <size>0.0339 0.1354 0.203</size>
            </box>
          </geometry>
          <surface>
            <contact>
              <ode>
                <max_vel>0.1</max_vel>
                <min_depth>0.001</min_depth>
              </ode>
            </contact>
            <friction>
              <ode>
                <mu>1</mu>
                <mu2>1</mu2>
              </ode>
              <torsional>
                <ode/>
              </torsional>
            </friction>
            <bounce/>
          </surface>
          <max_contacts>10</max_contacts>
        </collision>
        <collision name='back'>
          <pose frame=''>-0.18625 0 0.1016 0 -0 0</pose>
          <geometry>
            <box>
              <size>0.0339 0.1354 0.203</size>
            </box>
          </geometry>
          <surface>
            <contact>
              <ode>
                <max_vel>0.1</max_vel>
                <min_depth>0.001</min_depth>
              </ode>
            </contact>
            <friction>
              <ode>
                <mu>1</mu>
                <mu2>1</mu2>
              </ode>
              <torsional>
                <ode/>
              </torsional>
            </friction>
            <bounce/>
          </surface>
          <max_contacts>10</max_contacts>
        </collision>
        <self_collide>0</self_collide>
        <enable_wind>0</enable_wind>
        <kinematic>0</kinematic>
      </link>
      <pose frame=''>-10.1759 -2.5943 0 0 -0 0</pose>
    </model>
    <model name='gazebo'>
      <static>1</static>
      <link name='link'>
        <collision name='collision'>
          <geometry>
            <mesh>
              <scale>3 3 2.5</scale>
              <uri>model://gazebo/meshes/gazebo.dae</uri>
            </mesh>
          </geometry>
          <max_contacts>10</max_contacts>
          <surface>
            <contact>
              <ode/>
            </contact>
            <bounce/>
            <friction>
              <torsional>
                <ode/>
              </torsional>
              <ode/>
            </friction>
          </surface>
        </collision>
        <visual name='visual'>
          <geometry>
            <mesh>
              <scale>3 3 2.5</scale>
              <uri>model://gazebo/meshes/gazebo.dae</uri>
            </mesh>
          </geometry>
        </visual>
        <self_collide>0</self_collide>
        <enable_wind>0</enable_wind>
        <kinematic>0</kinematic>
      </link>
      <pose frame=''>-8.95114 2.72054 0 0 -0 0</pose>
    </model>
    <model name='Construction Cone'>
      <link name='link'>
        <collision name='collision'>
          <geometry>
            <mesh>
              <scale>10 10 10</scale>
              <uri>model://construction_cone/meshes/construction_cone.dae</uri>
            </mesh>
          </geometry>
          <max_contacts>10</max_contacts>
          <surface>
            <contact>
              <ode/>
            </contact>
            <bounce/>
            <friction>
              <torsional>
                <ode/>
              </torsional>
              <ode/>
            </friction>
          </surface>
        </collision>
        <visual name='visual'>
          <geometry>
            <mesh>
              <scale>10 10 10</scale>
              <uri>model://construction_cone/meshes/construction_cone.dae</uri>
            </mesh>
          </geometry>
        </visual>
        <self_collide>0</self_collide>
        <inertial>
          <pose frame=''>0 0 0 0 -0 0</pose>
          <inertia>
            <ixx>1</ixx>
            <ixy>0</ixy>
            <ixz>0</ixz>
            <iyy>1</iyy>
            <iyz>0</iyz>
            <izz>1</izz>
          </inertia>
          <mass>1</mass>
        </inertial>
        <enable_wind>0</enable_wind>
        <kinematic>0</kinematic>
      </link>
      <pose frame=''>-11.8761 -1.92527 0 0 -0 0</pose>
    </model>
    <model name='Construction Cone_0'>
      <link name='link'>
        <collision name='collision'>
          <geometry>
            <mesh>
              <scale>10 10 10</scale>
              <uri>model://construction_cone/meshes/construction_cone.dae</uri>
            </mesh>
          </geometry>
          <max_contacts>10</max_contacts>
          <surface>
            <contact>
              <ode/>
            </contact>
            <bounce/>
            <friction>
              <torsional>
                <ode/>
              </torsional>
              <ode/>
            </friction>
          </surface>
        </collision>
        <visual name='visual'>
          <geometry>
            <mesh>
              <scale>10 10 10</scale>
              <uri>model://construction_cone/meshes/construction_cone.dae</uri>
            </mesh>
          </geometry>
        </visual>
        <self_collide>0</self_collide>
        <inertial>
          <pose frame=''>0 0 0 0 -0 0</pose>
          <inertia>
            <ixx>1</ixx>
            <ixy>0</ixy>
            <ixz>0</ixz>
            <iyy>1</iyy>
            <iyz>0</iyz>
            <izz>1</izz>
          </inertia>
          <mass>1</mass>
        </inertial>
        <enable_wind>0</enable_wind>
        <kinematic>0</kinematic>
      </link>
      <pose frame=''>-11.4937 -2.48057 0 0 -0 0</pose>
    </model>
    <model name='cessna_c172'>
      <pose frame=''>-8.50337 13.8646 0.495 0 -0 0</pose>
      <link name='body'>
        <inertial>
          <mass>680.389</mass>
          <inertia>
            <ixx>1285.32</ixx>
            <ixy>0</ixy>
            <iyy>1824.93</iyy>
            <ixz>0</ixz>
            <iyz>0</iyz>
            <izz>2666.89</izz>
          </inertia>
          <pose frame=''>-0.0414 0 0.9271 0 -0 0</pose>
        </inertial>
        <collision name='collision'>
          <geometry>
            <mesh>
              <uri>model://cessna/meshes/body.dae</uri>
            </mesh>
          </geometry>
          <max_contacts>10</max_contacts>
          <surface>
            <contact>
              <ode/>
            </contact>
            <bounce/>
            <friction>
              <torsional>
                <ode/>
              </torsional>
              <ode/>
            </friction>
          </surface>
        </collision>
        <visual name='visual'>
          <geometry>
            <mesh>
              <uri>model://cessna/meshes/body.dae</uri>
            </mesh>
          </geometry>
        </visual>
        <self_collide>0</self_collide>
        <enable_wind>0</enable_wind>
        <kinematic>0</kinematic>
      </link>
      <link name='left_aileron'>
        <inertial>
          <mass>2</mass>
          <inertia>
            <ixx>0.8434</ixx>
            <ixy>0</ixy>
            <iyy>0.0119</iyy>
            <ixz>0</ixz>
            <iyz>0</iyz>
            <izz>0.855</izz>
          </inertia>
          <pose frame=''>-1.65 3.7 1.5 0.05 -0 -0.12</pose>
        </inertial>
        <collision name='collision'>
          <geometry>
            <mesh>
              <uri>model://cessna/meshes/left_aileron.dae</uri>
            </mesh>
          </geometry>
          <max_contacts>10</max_contacts>
          <surface>
            <contact>
              <ode/>
            </contact>
            <bounce/>
            <friction>
              <torsional>
                <ode/>
              </torsional>
              <ode/>
            </friction>
          </surface>
        </collision>
        <visual name='visual'>
          <geometry>
            <mesh>
              <uri>model://cessna/meshes/left_aileron.dae</uri>
            </mesh>
          </geometry>
        </visual>
        <self_collide>0</self_collide>
        <enable_wind>0</enable_wind>
        <kinematic>0</kinematic>
      </link>
      <link name='left_flap'>
        <inertial>
          <mass>2</mass>
          <inertia>
            <ixx>0.6747</ixx>
            <ixy>0</ixy>
            <iyy>0.0242</iyy>
            <ixz>0</ixz>
            <iyz>0</iyz>
            <izz>0.6962</izz>
          </inertia>
          <pose frame=''>-1.8 1.55 1.43 0.02 -0 0</pose>
        </inertial>
        <collision name='collision'>
          <geometry>
            <mesh>
              <uri>model://cessna/meshes/left_flap.dae</uri>
            </mesh>
          </geometry>
          <max_contacts>10</max_contacts>
          <surface>
            <contact>
              <ode/>
            </contact>
            <bounce/>
            <friction>
              <torsional>
                <ode/>
              </torsional>
              <ode/>
            </friction>
          </surface>
        </collision>
        <visual name='visual'>
          <geometry>
            <mesh>
              <uri>model://cessna/meshes/left_flap.dae</uri>
            </mesh>
          </geometry>
        </visual>
        <self_collide>0</self_collide>
        <enable_wind>0</enable_wind>
        <kinematic>0</kinematic>
      </link>
      <link name='right_aileron'>
        <inertial>
          <mass>2</mass>
          <inertia>
            <ixx>0.8434</ixx>
            <ixy>0</ixy>
            <iyy>0.0119</iyy>
            <ixz>0</ixz>
            <iyz>0</iyz>
            <izz>0.855</izz>
          </inertia>
          <pose frame=''>-1.65 -3.7 1.5 -0.05 -0 0.12</pose>
        </inertial>
        <collision name='collision'>
          <geometry>
            <mesh>
              <uri>model://cessna/meshes/right_aileron.dae</uri>
            </mesh>
          </geometry>
          <max_contacts>10</max_contacts>
          <surface>
            <contact>
              <ode/>
            </contact>
            <bounce/>
            <friction>
              <torsional>
                <ode/>
              </torsional>
              <ode/>
            </friction>
          </surface>
        </collision>
        <visual name='visual'>
          <geometry>
            <mesh>
              <uri>model://cessna/meshes/right_aileron.dae</uri>
            </mesh>
          </geometry>
        </visual>
        <self_collide>0</self_collide>
        <enable_wind>0</enable_wind>
        <kinematic>0</kinematic>
      </link>
      <link name='right_flap'>
        <inertial>
          <mass>2</mass>
          <inertia>
            <ixx>0.6747</ixx>
            <ixy>0</ixy>
            <iyy>0.0242</iyy>
            <ixz>0</ixz>
            <iyz>0</iyz>
            <izz>0.6962</izz>
          </inertia>
          <pose frame=''>-1.8 -1.55 1.43 -0.02 0 0</pose>
        </inertial>
        <collision name='collision'>
          <geometry>
            <mesh>
              <uri>model://cessna/meshes/right_flap.dae</uri>
            </mesh>
          </geometry>
          <max_contacts>10</max_contacts>
          <surface>
            <contact>
              <ode/>
            </contact>
            <bounce/>
            <friction>
              <torsional>
                <ode/>
              </torsional>
              <ode/>
            </friction>
          </surface>
        </collision>
        <visual name='visual'>
          <geometry>
            <mesh>
              <uri>model://cessna/meshes/right_flap.dae</uri>
            </mesh>
          </geometry>
        </visual>
        <self_collide>0</self_collide>
        <enable_wind>0</enable_wind>
        <kinematic>0</kinematic>
      </link>
      <link name='elevators'>
        <inertial>
          <mass>2</mass>
          <inertia>
            <ixx>1.5008</ixx>
            <ixy>0</ixy>
            <iyy>0.0274</iyy>
            <ixz>0</ixz>
            <iyz>0</iyz>
            <izz>1.5266</izz>
          </inertia>
          <pose frame=''>-5.75 0 0.57 0 -0 0</pose>
        </inertial>
        <collision name='collision'>
          <geometry>
            <mesh>
              <uri>model://cessna/meshes/elevators.dae</uri>
            </mesh>
          </geometry>
          <max_contacts>10</max_contacts>
          <surface>
            <contact>
              <ode/>
            </contact>
            <bounce/>
            <friction>
              <torsional>
                <ode/>
              </torsional>
              <ode/>
            </friction>
          </surface>
        </collision>
        <visual name='visual'>
          <geometry>
            <mesh>
              <uri>model://cessna/meshes/elevators.dae</uri>
            </mesh>
          </geometry>
        </visual>
        <self_collide>0</self_collide>
        <enable_wind>0</enable_wind>
        <kinematic>0</kinematic>
      </link>
      <link name='rudder'>
        <inertial>
          <mass>2</mass>
          <inertia>
            <ixx>0.4708</ixx>
            <ixy>0</ixy>
            <iyy>0.5208</iyy>
            <ixz>0</ixz>
            <iyz>0</iyz>
            <izz>0.0508</izz>
          </inertia>
          <pose frame=''>-6.1 0 1.3 0 -0.35 0</pose>
        </inertial>
        <collision name='collision'>
          <geometry>
            <mesh>
              <uri>model://cessna/meshes/rudder.dae</uri>
            </mesh>
          </geometry>
          <max_contacts>10</max_contacts>
          <surface>
            <contact>
              <ode/>
            </contact>
            <bounce/>
            <friction>
              <torsional>
                <ode/>
              </torsional>
              <ode/>
            </friction>
          </surface>
        </collision>
        <visual name='visual'>
          <geometry>
            <mesh>
              <uri>model://cessna/meshes/rudder.dae</uri>
            </mesh>
          </geometry>
        </visual>
        <self_collide>0</self_collide>
        <enable_wind>0</enable_wind>
        <kinematic>0</kinematic>
      </link>
      <link name='propeller'>
        <pose frame=''>1.79 0 0.855 0 -0 0</pose>
        <inertial>
          <mass>18.37</mass>
          <inertia>
            <ixx>7.5067</ixx>
            <ixy>0</ixy>
            <iyy>7.515</iyy>
            <ixz>0</ixz>
            <iyz>0</iyz>
            <izz>0.068275</izz>
          </inertia>
          <pose frame=''>-0.35 0 0 0 -0 0</pose>
        </inertial>
        <collision name='collision'>
          <geometry>
            <mesh>
              <uri>model://cessna/meshes/cessna_prop.dae</uri>
            </mesh>
          </geometry>
          <max_contacts>10</max_contacts>
          <surface>
            <contact>
              <ode/>
            </contact>
            <bounce/>
            <friction>
              <torsional>
                <ode/>
              </torsional>
              <ode/>
            </friction>
          </surface>
        </collision>
        <visual name='visual'>
          <geometry>
            <mesh>
              <uri>model://cessna/meshes/cessna_prop.dae</uri>
            </mesh>
          </geometry>
        </visual>
        <self_collide>0</self_collide>
        <enable_wind>0</enable_wind>
        <kinematic>0</kinematic>
      </link>
      <link name='front_wheel'>
        <inertial>
          <mass>2</mass>
          <inertia>
            <ixx>0.01786</ixx>
            <ixy>0</ixy>
            <iyy>0.01786</iyy>
            <ixz>0</ixz>
            <iyz>0</iyz>
            <izz>0.0324</izz>
          </inertia>
          <pose frame=''>0.712 0 -0.313 1.57079 -0 0</pose>
        </inertial>
        <collision name='collision'>
          <pose frame=''>0.712 0 -0.313 1.57079 -0 0</pose>
          <geometry>
            <cylinder>
              <radius>0.18</radius>
              <length>0.1</length>
            </cylinder>
          </geometry>
          <surface>
            <friction>
              <ode>
                <mu>0.3</mu>
                <mu2>0.3</mu2>
              </ode>
              <torsional>
                <ode/>
              </torsional>
            </friction>
            <contact>
              <ode>
                <max_vel>0.1</max_vel>
                <min_depth>0.001</min_depth>
              </ode>
            </contact>
            <bounce/>
          </surface>
          <max_contacts>10</max_contacts>
        </collision>
        <visual name='visual'>
          <geometry>
            <mesh>
              <uri>model://cessna/meshes/cessna_front_wheel.dae</uri>
            </mesh>
          </geometry>
        </visual>
        <self_collide>0</self_collide>
        <enable_wind>0</enable_wind>
        <kinematic>0</kinematic>
      </link>
      <link name='rear_left_wheel'>
        <inertial>
          <mass>2</mass>
          <inertia>
            <ixx>0.035516</ixx>
            <ixy>0</ixy>
            <iyy>0.035516</iyy>
            <ixz>0</ixz>
            <iyz>0</iyz>
            <izz>0.0625</izz>
          </inertia>
          <pose frame=''>-1 1.27 -0.25 1.57079 -0 0</pose>
        </inertial>
        <collision name='collision'>
          <pose frame=''>-1 1.27 -0.25 1.57079 -0 0</pose>
          <geometry>
            <cylinder>
              <radius>0.25</radius>
              <length>0.16</length>
            </cylinder>
          </geometry>
          <surface>
            <friction>
              <ode>
                <mu>0.3</mu>
                <mu2>0.3</mu2>
              </ode>
              <torsional>
                <ode/>
              </torsional>
            </friction>
            <contact>
              <ode>
                <max_vel>0.1</max_vel>
                <min_depth>0.001</min_depth>
              </ode>
            </contact>
            <bounce/>
          </surface>
          <max_contacts>10</max_contacts>
        </collision>
        <visual name='visual'>
          <geometry>
            <mesh>
              <uri>model://cessna/meshes/cessna_rear_left_wheel.dae</uri>
            </mesh>
          </geometry>
        </visual>
        <self_collide>0</self_collide>
        <enable_wind>0</enable_wind>
        <kinematic>0</kinematic>
      </link>
      <link name='rear_right_wheel'>
        <inertial>
          <mass>2</mass>
          <inertia>
            <ixx>0.035516</ixx>
            <ixy>0</ixy>
            <iyy>0.035516</iyy>
            <ixz>0</ixz>
            <iyz>0</iyz>
            <izz>0.0625</izz>
          </inertia>
          <pose frame=''>-1 -1.27 -0.25 1.57079 -0 0</pose>
        </inertial>
        <collision name='collision'>
          <pose frame=''>-1 -1.27 -0.25 1.57079 -0 0</pose>
          <geometry>
            <cylinder>
              <radius>0.25</radius>
              <length>0.16</length>
            </cylinder>
          </geometry>
          <surface>
            <friction>
              <ode>
                <mu>0.3</mu>
                <mu2>0.3</mu2>
              </ode>
              <torsional>
                <ode/>
              </torsional>
            </friction>
            <contact>
              <ode>
                <max_vel>0.1</max_vel>
                <min_depth>0.001</min_depth>
              </ode>
            </contact>
            <bounce/>
          </surface>
          <max_contacts>10</max_contacts>
        </collision>
        <visual name='visual'>
          <geometry>
            <mesh>
              <uri>model://cessna/meshes/cessna_rear_right_wheel.dae</uri>
            </mesh>
          </geometry>
        </visual>
        <self_collide>0</self_collide>
        <enable_wind>0</enable_wind>
        <kinematic>0</kinematic>
      </link>
      <joint name='left_flap_joint' type='revolute'>
        <parent>body</parent>
        <child>left_flap</child>
        <pose frame=''>-1.6 1.55 1.43 0.02 -0 0</pose>
        <axis>
          <xyz>0 1 0</xyz>
          <limit>
            <lower>-0.53</lower>
            <upper>0.53</upper>
            <effort>-1</effort>
            <velocity>-1</velocity>
          </limit>
          <dynamics>
            <damping>1</damping>
            <spring_reference>0</spring_reference>
            <spring_stiffness>0</spring_stiffness>
          </dynamics>
          <use_parent_model_frame>0</use_parent_model_frame>
        </axis>
        <physics>
          <ode>
            <implicit_spring_damper>1</implicit_spring_damper>
            <limit>
              <cfm>0</cfm>
              <erp>0.2</erp>
            </limit>
          </ode>
        </physics>
      </joint>
      <joint name='left_aileron_joint' type='revolute'>
        <parent>body</parent>
        <child>left_aileron</child>
        <pose frame=''>-1.45 3.7 1.5 0.05 -0 -0.12</pose>
        <axis>
          <xyz>0 1 0</xyz>
          <limit>
            <lower>-0.53</lower>
            <upper>0.53</upper>
            <effort>-1</effort>
            <velocity>-1</velocity>
          </limit>
          <dynamics>
            <damping>1</damping>
            <spring_reference>0</spring_reference>
            <spring_stiffness>0</spring_stiffness>
          </dynamics>
          <use_parent_model_frame>0</use_parent_model_frame>
        </axis>
        <physics>
          <ode>
            <implicit_spring_damper>1</implicit_spring_damper>
            <limit>
              <cfm>0</cfm>
              <erp>0.2</erp>
            </limit>
          </ode>
        </physics>
      </joint>
      <joint name='right_flap_joint' type='revolute'>
        <parent>body</parent>
        <child>right_flap</child>
        <pose frame=''>-1.6 -1.55 1.43 -0.02 0 0</pose>
        <axis>
          <xyz>0 1 0</xyz>
          <limit>
            <lower>-0.53</lower>
            <upper>0.53</upper>
            <effort>-1</effort>
            <velocity>-1</velocity>
          </limit>
          <dynamics>
            <damping>1</damping>
            <spring_reference>0</spring_reference>
            <spring_stiffness>0</spring_stiffness>
          </dynamics>
          <use_parent_model_frame>0</use_parent_model_frame>
        </axis>
        <physics>
          <ode>
            <implicit_spring_damper>1</implicit_spring_damper>
            <limit>
              <cfm>0</cfm>
              <erp>0.2</erp>
            </limit>
          </ode>
        </physics>
      </joint>
      <joint name='right_aileron_joint' type='revolute'>
        <parent>body</parent>
        <child>right_aileron</child>
        <pose frame=''>-1.45 -3.7 1.5 -0.05 -0 0.12</pose>
        <axis>
          <xyz>0 1 0</xyz>
          <limit>
            <lower>-0.53</lower>
            <upper>0.53</upper>
            <effort>-1</effort>
            <velocity>-1</velocity>
          </limit>
          <dynamics>
            <damping>1</damping>
            <spring_reference>0</spring_reference>
            <spring_stiffness>0</spring_stiffness>
          </dynamics>
          <use_parent_model_frame>0</use_parent_model_frame>
        </axis>
        <physics>
          <ode>
            <implicit_spring_damper>1</implicit_spring_damper>
            <limit>
              <cfm>0</cfm>
              <erp>0.2</erp>
            </limit>
          </ode>
        </physics>
      </joint>
      <joint name='elevators_joint' type='revolute'>
        <parent>body</parent>
        <child>elevators</child>
        <pose frame=''>-5.55 0 0.57 0 -0 0</pose>
        <axis>
          <xyz>0 1 0</xyz>
          <limit>
            <lower>-0.53</lower>
            <upper>0.53</upper>
            <effort>-1</effort>
            <velocity>-1</velocity>
          </limit>
          <dynamics>
            <damping>1</damping>
            <spring_reference>0</spring_reference>
            <spring_stiffness>0</spring_stiffness>
          </dynamics>
          <use_parent_model_frame>0</use_parent_model_frame>
        </axis>
        <physics>
          <ode>
            <implicit_spring_damper>1</implicit_spring_damper>
            <limit>
              <cfm>0</cfm>
              <erp>0.2</erp>
            </limit>
          </ode>
        </physics>
      </joint>
      <joint name='rudder_joint' type='revolute'>
        <parent>body</parent>
        <child>rudder</child>
        <pose frame=''>-5.9 0 1.3 0 -0.35 0</pose>
        <axis>
          <xyz>0 0 1</xyz>
          <limit>
            <lower>-0.53</lower>
            <upper>0.53</upper>
            <effort>-1</effort>
            <velocity>-1</velocity>
          </limit>
          <dynamics>
            <damping>1</damping>
            <spring_reference>0</spring_reference>
            <spring_stiffness>0</spring_stiffness>
          </dynamics>
          <use_parent_model_frame>0</use_parent_model_frame>
        </axis>
        <physics>
          <ode>
            <implicit_spring_damper>1</implicit_spring_damper>
            <limit>
              <cfm>0</cfm>
              <erp>0.2</erp>
            </limit>
          </ode>
        </physics>
      </joint>
      <joint name='propeller_joint' type='revolute'>
        <parent>body</parent>
        <child>propeller</child>
        <axis>
          <xyz>1 0 0</xyz>
          <limit>
            <lower>-1e+12</lower>
            <upper>1e+12</upper>
            <effort>-1</effort>
            <velocity>-1</velocity>
          </limit>
          <dynamics>
            <damping>0.001</damping>
            <spring_reference>0</spring_reference>
            <spring_stiffness>0</spring_stiffness>
          </dynamics>
          <use_parent_model_frame>0</use_parent_model_frame>
        </axis>
        <physics>
          <ode>
            <implicit_spring_damper>1</implicit_spring_damper>
            <limit>
              <cfm>0</cfm>
              <erp>0.2</erp>
            </limit>
          </ode>
        </physics>
      </joint>
      <joint name='front_wheel_joint' type='revolute'>
        <parent>body</parent>
        <child>front_wheel</child>
        <pose frame=''>0.712 0 -0.313 0 -0 0</pose>
        <axis>
          <xyz>0 1 0</xyz>
          <limit>
            <lower>-1e+12</lower>
            <upper>1e+12</upper>
            <effort>-1</effort>
            <velocity>-1</velocity>
          </limit>
          <dynamics>
            <damping>0.01</damping>
            <spring_reference>0</spring_reference>
            <spring_stiffness>0</spring_stiffness>
          </dynamics>
          <use_parent_model_frame>0</use_parent_model_frame>
        </axis>
        <physics>
          <ode>
            <implicit_spring_damper>1</implicit_spring_damper>
            <limit>
              <cfm>0</cfm>
              <erp>0.2</erp>
            </limit>
          </ode>
        </physics>
      </joint>
      <joint name='rear_left_wheel_joint' type='revolute'>
        <parent>body</parent>
        <child>rear_left_wheel</child>
        <pose frame=''>-1 -1.27 -0.25 0 -0 0</pose>
        <axis>
          <xyz>0 1 0</xyz>
          <limit>
            <lower>-1e+12</lower>
            <upper>1e+12</upper>
            <effort>-1</effort>
            <velocity>-1</velocity>
          </limit>
          <dynamics>
            <damping>0.01</damping>
            <spring_reference>0</spring_reference>
            <spring_stiffness>0</spring_stiffness>
          </dynamics>
          <use_parent_model_frame>0</use_parent_model_frame>
        </axis>
        <physics>
          <ode>
            <implicit_spring_damper>1</implicit_spring_damper>
            <limit>
              <cfm>0</cfm>
              <erp>0.2</erp>
            </limit>
          </ode>
        </physics>
      </joint>
      <joint name='rear_right_wheel_joint' type='revolute'>
        <parent>body</parent>
        <child>rear_right_wheel</child>
        <pose frame=''>-1 1.27 -0.25 0 -0 0</pose>
        <axis>
          <xyz>0 1 0</xyz>
          <limit>
            <lower>-1e+12</lower>
            <upper>1e+12</upper>
            <effort>-1</effort>
            <velocity>-1</velocity>
          </limit>
          <dynamics>
            <damping>0.01</damping>
            <spring_reference>0</spring_reference>
            <spring_stiffness>0</spring_stiffness>
          </dynamics>
          <use_parent_model_frame>0</use_parent_model_frame>
        </axis>
        <physics>
          <ode>
            <implicit_spring_damper>1</implicit_spring_damper>
            <limit>
              <cfm>0</cfm>
              <erp>0.2</erp>
            </limit>
          </ode>
        </physics>
      </joint>
    </model>
    <model name='Construction Cone_1'>
      <link name='link'>
        <collision name='collision'>
          <geometry>
            <mesh>
              <scale>10 10 10</scale>
              <uri>model://construction_cone/meshes/construction_cone.dae</uri>
            </mesh>
          </geometry>
          <max_contacts>10</max_contacts>
          <surface>
            <contact>
              <ode/>
            </contact>
            <bounce/>
            <friction>
              <torsional>
                <ode/>
              </torsional>
              <ode/>
            </friction>
          </surface>
        </collision>
        <visual name='visual'>
          <geometry>
            <mesh>
              <scale>10 10 10</scale>
              <uri>model://construction_cone/meshes/construction_cone.dae</uri>
            </mesh>
          </geometry>
        </visual>
        <self_collide>0</self_collide>
        <inertial>
          <pose frame=''>0 0 0 0 -0 0</pose>
          <inertia>
            <ixx>1</ixx>
            <ixy>0</ixy>
            <ixz>0</ixz>
            <iyy>1</iyy>
            <iyz>0</iyz>
            <izz>1</izz>
          </inertia>
          <mass>1</mass>
        </inertial>
        <enable_wind>0</enable_wind>
        <kinematic>0</kinematic>
      </link>
      <pose frame=''>-13.1213 22.9239 0 0 -0 0</pose>
    </model>
    <model name='Construction Cone_2'>
      <link name='link'>
        <collision name='collision'>
          <geometry>
            <mesh>
              <scale>10 10 10</scale>
              <uri>model://construction_cone/meshes/construction_cone.dae</uri>
            </mesh>
          </geometry>
          <max_contacts>10</max_contacts>
          <surface>
            <contact>
              <ode/>
            </contact>
            <bounce/>
            <friction>
              <torsional>
                <ode/>
              </torsional>
              <ode/>
            </friction>
          </surface>
        </collision>
        <visual name='visual'>
          <geometry>
            <mesh>
              <scale>10 10 10</scale>
              <uri>model://construction_cone/meshes/construction_cone.dae</uri>
            </mesh>
          </geometry>
        </visual>
        <self_collide>0</self_collide>
        <inertial>
          <pose frame=''>0 0 0 0 -0 0</pose>
          <inertia>
            <ixx>1</ixx>
            <ixy>0</ixy>
            <ixz>0</ixz>
            <iyy>1</iyy>
            <iyz>0</iyz>
            <izz>1</izz>
          </inertia>
          <mass>1</mass>
        </inertial>
        <enable_wind>0</enable_wind>
        <kinematic>0</kinematic>
      </link>
      <pose frame=''>-14.4173 26.8144 0 0 -0 0</pose>
    </model>
    <model name='Construction Cone_3'>
      <link name='link'>
        <collision name='collision'>
          <geometry>
            <mesh>
              <scale>10 10 10</scale>
              <uri>model://construction_cone/meshes/construction_cone.dae</uri>
            </mesh>
          </geometry>
          <max_contacts>10</max_contacts>
          <surface>
            <contact>
              <ode/>
            </contact>
            <bounce/>
            <friction>
              <torsional>
                <ode/>
              </torsional>
              <ode/>
            </friction>
          </surface>
        </collision>
        <visual name='visual'>
          <geometry>
            <mesh>
              <scale>10 10 10</scale>
              <uri>model://construction_cone/meshes/construction_cone.dae</uri>
            </mesh>
          </geometry>
        </visual>
        <self_collide>0</self_collide>
        <inertial>
          <pose frame=''>0 0 0 0 -0 0</pose>
          <inertia>
            <ixx>1</ixx>
            <ixy>0</ixy>
            <ixz>0</ixz>
            <iyy>1</iyy>
            <iyz>0</iyz>
            <izz>1</izz>
          </inertia>
          <mass>1</mass>
        </inertial>
        <enable_wind>0</enable_wind>
        <kinematic>0</kinematic>
      </link>
      <pose frame=''>-16.8803 34.8919 0 0 -0 0</pose>
    </model>
    <model name='Construction Cone_4'>
      <link name='link'>
        <collision name='collision'>
          <geometry>
            <mesh>
              <scale>10 10 10</scale>
              <uri>model://construction_cone/meshes/construction_cone.dae</uri>
            </mesh>
          </geometry>
          <max_contacts>10</max_contacts>
          <surface>
            <contact>
              <ode/>
            </contact>
            <bounce/>
            <friction>
              <torsional>
                <ode/>
              </torsional>
              <ode/>
            </friction>
          </surface>
        </collision>
        <visual name='visual'>
          <geometry>
            <mesh>
              <scale>10 10 10</scale>
              <uri>model://construction_cone/meshes/construction_cone.dae</uri>
            </mesh>
          </geometry>
        </visual>
        <self_collide>0</self_collide>
        <inertial>
          <pose frame=''>0 0 0 0 -0 0</pose>
          <inertia>
            <ixx>1</ixx>
            <ixy>0</ixy>
            <ixz>0</ixz>
            <iyy>1</iyy>
            <iyz>0</iyz>
            <izz>1</izz>
          </inertia>
          <mass>1</mass>
        </inertial>
        <enable_wind>0</enable_wind>
        <kinematic>0</kinematic>
      </link>
      <pose frame=''>-15.4702 30.6217 0 0 -0 0</pose>
    </model>
    <model name='Construction Cone_5'>
      <link name='link'>
        <collision name='collision'>
          <geometry>
            <mesh>
              <scale>10 10 10</scale>
              <uri>model://construction_cone/meshes/construction_cone.dae</uri>
            </mesh>
          </geometry>
          <max_contacts>10</max_contacts>
          <surface>
            <contact>
              <ode/>
            </contact>
            <bounce/>
            <friction>
              <torsional>
                <ode/>
              </torsional>
              <ode/>
            </friction>
          </surface>
        </collision>
        <visual name='visual'>
          <geometry>
            <mesh>
              <scale>10 10 10</scale>
              <uri>model://construction_cone/meshes/construction_cone.dae</uri>
            </mesh>
          </geometry>
        </visual>
        <self_collide>0</self_collide>
        <inertial>
          <pose frame=''>0 0 0 0 -0 0</pose>
          <inertia>
            <ixx>1</ixx>
            <ixy>0</ixy>
            <ixz>0</ixz>
            <iyy>1</iyy>
            <iyz>0</iyz>
            <izz>1</izz>
          </inertia>
          <mass>1</mass>
        </inertial>
        <enable_wind>0</enable_wind>
        <kinematic>0</kinematic>
      </link>
      <pose frame=''>-18.8748 40.8502 0 0 -0 0</pose>
    </model>
    <model name='Construction Cone_6'>
      <link name='link'>
        <collision name='collision'>
          <geometry>
            <mesh>
              <scale>10 10 10</scale>
              <uri>model://construction_cone/meshes/construction_cone.dae</uri>
            </mesh>
          </geometry>
          <max_contacts>10</max_contacts>
          <surface>
            <contact>
              <ode/>
            </contact>
            <bounce/>
            <friction>
              <torsional>
                <ode/>
              </torsional>
              <ode/>
            </friction>
          </surface>
        </collision>
        <visual name='visual'>
          <geometry>
            <mesh>
              <scale>10 10 10</scale>
              <uri>model://construction_cone/meshes/construction_cone.dae</uri>
            </mesh>
          </geometry>
        </visual>
        <self_collide>0</self_collide>
        <inertial>
          <pose frame=''>0 0 0 0 -0 0</pose>
          <inertia>
            <ixx>1</ixx>
            <ixy>0</ixy>
            <ixz>0</ixz>
            <iyy>1</iyy>
            <iyz>0</iyz>
            <izz>1</izz>
          </inertia>
          <mass>1</mass>
        </inertial>
        <enable_wind>0</enable_wind>
        <kinematic>0</kinematic>
      </link>
      <pose frame=''>-20.9265 21.2475 0 0 -0 0</pose>
    </model>
    <model name='Construction Cone_7'>
      <link name='link'>
        <collision name='collision'>
          <geometry>
            <mesh>
              <scale>10 10 10</scale>
              <uri>model://construction_cone/meshes/construction_cone.dae</uri>
            </mesh>
          </geometry>
          <max_contacts>10</max_contacts>
          <surface>
            <contact>
              <ode/>
            </contact>
            <bounce/>
            <friction>
              <torsional>
                <ode/>
              </torsional>
              <ode/>
            </friction>
          </surface>
        </collision>
        <visual name='visual'>
          <geometry>
            <mesh>
              <scale>10 10 10</scale>
              <uri>model://construction_cone/meshes/construction_cone.dae</uri>
            </mesh>
          </geometry>
        </visual>
        <self_collide>0</self_collide>
        <inertial>
          <pose frame=''>0 0 0 0 -0 0</pose>
          <inertia>
            <ixx>1</ixx>
            <ixy>0</ixy>
            <ixz>0</ixz>
            <iyy>1</iyy>
            <iyz>0</iyz>
            <izz>1</izz>
          </inertia>
          <mass>1</mass>
        </inertial>
        <enable_wind>0</enable_wind>
        <kinematic>0</kinematic>
      </link>
      <pose frame=''>-22.1856 24.8586 0 0 -0 0</pose>
    </model>
    <model name='Construction Cone_8'>
      <link name='link'>
        <collision name='collision'>
          <geometry>
            <mesh>
              <scale>10 10 10</scale>
              <uri>model://construction_cone/meshes/construction_cone.dae</uri>
            </mesh>
          </geometry>
          <max_contacts>10</max_contacts>
          <surface>
            <contact>
              <ode/>
            </contact>
            <bounce/>
            <friction>
              <torsional>
                <ode/>
              </torsional>
              <ode/>
            </friction>
          </surface>
        </collision>
        <visual name='visual'>
          <geometry>
            <mesh>
              <scale>10 10 10</scale>
              <uri>model://construction_cone/meshes/construction_cone.dae</uri>
            </mesh>
          </geometry>
        </visual>
        <self_collide>0</self_collide>
        <inertial>
          <pose frame=''>0 0 0 0 -0 0</pose>
          <inertia>
            <ixx>1</ixx>
            <ixy>0</ixy>
            <ixz>0</ixz>
            <iyy>1</iyy>
            <iyz>0</iyz>
            <izz>1</izz>
          </inertia>
          <mass>1</mass>
        </inertial>
        <enable_wind>0</enable_wind>
        <kinematic>0</kinematic>
      </link>
      <pose frame=''>-23.1731 28.9611 0 0 -0 0</pose>
    </model>
    <model name='Construction Cone_9'>
      <link name='link'>
        <collision name='collision'>
          <geometry>
            <mesh>
              <scale>10 10 10</scale>
              <uri>model://construction_cone/meshes/construction_cone.dae</uri>
            </mesh>
          </geometry>
          <max_contacts>10</max_contacts>
          <surface>
            <contact>
              <ode/>
            </contact>
            <bounce/>
            <friction>
              <torsional>
                <ode/>
              </torsional>
              <ode/>
            </friction>
          </surface>
        </collision>
        <visual name='visual'>
          <geometry>
            <mesh>
              <scale>10 10 10</scale>
              <uri>model://construction_cone/meshes/construction_cone.dae</uri>
            </mesh>
          </geometry>
        </visual>
        <self_collide>0</self_collide>
        <inertial>
          <pose frame=''>0 0 0 0 -0 0</pose>
          <inertia>
            <ixx>1</ixx>
            <ixy>0</ixy>
            <ixz>0</ixz>
            <iyy>1</iyy>
            <iyz>0</iyz>
            <izz>1</izz>
          </inertia>
          <mass>1</mass>
        </inertial>
        <enable_wind>0</enable_wind>
        <kinematic>0</kinematic>
      </link>
      <pose frame=''>-24.6237 33.1476 0 0 -0 0</pose>
    </model>
    <model name='Construction Cone_10'>
      <link name='link'>
        <collision name='collision'>
          <geometry>
            <mesh>
              <scale>10 10 10</scale>
              <uri>model://construction_cone/meshes/construction_cone.dae</uri>
            </mesh>
          </geometry>
          <max_contacts>10</max_contacts>
          <surface>
            <contact>
              <ode/>
            </contact>
            <bounce/>
            <friction>
              <torsional>
                <ode/>
              </torsional>
              <ode/>
            </friction>
          </surface>
        </collision>
        <visual name='visual'>
          <geometry>
            <mesh>
              <scale>10 10 10</scale>
              <uri>model://construction_cone/meshes/construction_cone.dae</uri>
            </mesh>
          </geometry>
        </visual>
        <self_collide>0</self_collide>
        <inertial>
          <pose frame=''>0 0 0 0 -0 0</pose>
          <inertia>
            <ixx>1</ixx>
            <ixy>0</ixy>
            <ixz>0</ixz>
            <iyy>1</iyy>
            <iyz>0</iyz>
            <izz>1</izz>
          </inertia>
          <mass>1</mass>
        </inertial>
        <enable_wind>0</enable_wind>
        <kinematic>0</kinematic>
      </link>
      <pose frame=''>-26.5222 39.1001 0 0 -0 0</pose>
    </model>
    <model name='Construction Cone_11'>
      <link name='link'>
        <collision name='collision'>
          <geometry>
            <mesh>
              <scale>10 10 10</scale>
              <uri>model://construction_cone/meshes/construction_cone.dae</uri>
            </mesh>
          </geometry>
          <max_contacts>10</max_contacts>
          <surface>
            <contact>
              <ode/>
            </contact>
            <bounce/>
            <friction>
              <torsional>
                <ode/>
              </torsional>
              <ode/>
            </friction>
          </surface>
        </collision>
        <visual name='visual'>
          <geometry>
            <mesh>
              <scale>10 10 10</scale>
              <uri>model://construction_cone/meshes/construction_cone.dae</uri>
            </mesh>
          </geometry>
        </visual>
        <self_collide>0</self_collide>
        <inertial>
          <pose frame=''>0 0 0 0 -0 0</pose>
          <inertia>
            <ixx>1</ixx>
            <ixy>0</ixy>
            <ixz>0</ixz>
            <iyy>1</iyy>
            <iyz>0</iyz>
            <izz>1</izz>
          </inertia>
          <mass>1</mass>
        </inertial>
        <enable_wind>0</enable_wind>
        <kinematic>0</kinematic>
      </link>
      <pose frame=''>-23.9286 58.4712 0 0 -0 0</pose>
    </model>
    <model name='Construction Cone_12'>
      <link name='link'>
        <collision name='collision'>
          <geometry>
            <mesh>
              <scale>10 10 10</scale>
              <uri>model://construction_cone/meshes/construction_cone.dae</uri>
            </mesh>
          </geometry>
          <max_contacts>10</max_contacts>
          <surface>
            <contact>
              <ode/>
            </contact>
            <bounce/>
            <friction>
              <torsional>
                <ode/>
              </torsional>
              <ode/>
            </friction>
          </surface>
        </collision>
        <visual name='visual'>
          <geometry>
            <mesh>
              <scale>10 10 10</scale>
              <uri>model://construction_cone/meshes/construction_cone.dae</uri>
            </mesh>
          </geometry>
        </visual>
        <self_collide>0</self_collide>
        <inertial>
          <pose frame=''>0 0 0 0 -0 0</pose>
          <inertia>
            <ixx>1</ixx>
            <ixy>0</ixy>
            <ixz>0</ixz>
            <iyy>1</iyy>
            <iyz>0</iyz>
            <izz>1</izz>
          </inertia>
          <mass>1</mass>
        </inertial>
        <enable_wind>0</enable_wind>
        <kinematic>0</kinematic>
      </link>
      <pose frame=''>-32.5189 56.987 0 0 -0 0</pose>
    </model>
    <model name='Construction Cone_13'>
      <link name='link'>
        <collision name='collision'>
          <geometry>
            <mesh>
              <scale>10 10 10</scale>
              <uri>model://construction_cone/meshes/construction_cone.dae</uri>
            </mesh>
          </geometry>
          <max_contacts>10</max_contacts>
          <surface>
            <contact>
              <ode/>
            </contact>
            <bounce/>
            <friction>
              <torsional>
                <ode/>
              </torsional>
              <ode/>
            </friction>
          </surface>
        </collision>
        <visual name='visual'>
          <geometry>
            <mesh>
              <scale>10 10 10</scale>
              <uri>model://construction_cone/meshes/construction_cone.dae</uri>
            </mesh>
          </geometry>
        </visual>
        <self_collide>0</self_collide>
        <inertial>
          <pose frame=''>0 0 0 0 -0 0</pose>
          <inertia>
            <ixx>1</ixx>
            <ixy>0</ixy>
            <ixz>0</ixz>
            <iyy>1</iyy>
            <iyz>0</iyz>
            <izz>1</izz>
          </inertia>
          <mass>1</mass>
        </inertial>
        <enable_wind>0</enable_wind>
        <kinematic>0</kinematic>
      </link>
      <pose frame=''>-27.5165 68.6698 0 0 -0 0</pose>
    </model>
    <model name='Construction Cone_14'>
      <link name='link'>
        <collision name='collision'>
          <geometry>
            <mesh>
              <scale>10 10 10</scale>
              <uri>model://construction_cone/meshes/construction_cone.dae</uri>
            </mesh>
          </geometry>
          <max_contacts>10</max_contacts>
          <surface>
            <contact>
              <ode/>
            </contact>
            <bounce/>
            <friction>
              <torsional>
                <ode/>
              </torsional>
              <ode/>
            </friction>
          </surface>
        </collision>
        <visual name='visual'>
          <geometry>
            <mesh>
              <scale>10 10 10</scale>
              <uri>model://construction_cone/meshes/construction_cone.dae</uri>
            </mesh>
          </geometry>
        </visual>
        <self_collide>0</self_collide>
        <inertial>
          <pose frame=''>0 0 0 0 -0 0</pose>
          <inertia>
            <ixx>1</ixx>
            <ixy>0</ixy>
            <ixz>0</ixz>
            <iyy>1</iyy>
            <iyz>0</iyz>
            <izz>1</izz>
          </inertia>
          <mass>1</mass>
        </inertial>
        <enable_wind>0</enable_wind>
        <kinematic>0</kinematic>
      </link>
      <pose frame=''>-37.022 70.7723 0 0 -0 0</pose>
    </model>
    <model name='Construction Cone_15'>
      <link name='link'>
        <collision name='collision'>
          <geometry>
            <mesh>
              <scale>10 10 10</scale>
              <uri>model://construction_cone/meshes/construction_cone.dae</uri>
            </mesh>
          </geometry>
          <max_contacts>10</max_contacts>
          <surface>
            <contact>
              <ode/>
            </contact>
            <bounce/>
            <friction>
              <torsional>
                <ode/>
              </torsional>
              <ode/>
            </friction>
          </surface>
        </collision>
        <visual name='visual'>
          <geometry>
            <mesh>
              <scale>10 10 10</scale>
              <uri>model://construction_cone/meshes/construction_cone.dae</uri>
            </mesh>
          </geometry>
        </visual>
        <self_collide>0</self_collide>
        <inertial>
          <pose frame=''>0 0 0 0 -0 0</pose>
          <inertia>
            <ixx>1</ixx>
            <ixy>0</ixy>
            <ixz>0</ixz>
            <iyy>1</iyy>
            <iyz>0</iyz>
            <izz>1</izz>
          </inertia>
          <mass>1</mass>
        </inertial>
        <enable_wind>0</enable_wind>
        <kinematic>0</kinematic>
      </link>
      <pose frame=''>-31.5591 87.9535 0 0 -0 0</pose>
    </model>
    <model name='Construction Cone_16'>
      <link name='link'>
        <collision name='collision'>
          <geometry>
            <mesh>
              <scale>10 10 10</scale>
              <uri>model://construction_cone/meshes/construction_cone.dae</uri>
            </mesh>
          </geometry>
          <max_contacts>10</max_contacts>
          <surface>
            <contact>
              <ode/>
            </contact>
            <bounce/>
            <friction>
              <torsional>
                <ode/>
              </torsional>
              <ode/>
            </friction>
          </surface>
        </collision>
        <visual name='visual'>
          <geometry>
            <mesh>
              <scale>10 10 10</scale>
              <uri>model://construction_cone/meshes/construction_cone.dae</uri>
            </mesh>
          </geometry>
        </visual>
        <self_collide>0</self_collide>
        <inertial>
          <pose frame=''>0 0 0 0 -0 0</pose>
          <inertia>
            <ixx>1</ixx>
            <ixy>0</ixy>
            <ixz>0</ixz>
            <iyy>1</iyy>
            <iyz>0</iyz>
            <izz>1</izz>
          </inertia>
          <mass>1</mass>
        </inertial>
        <enable_wind>0</enable_wind>
        <kinematic>0</kinematic>
      </link>
      <pose frame=''>-43.3965 89.815 0 0 -0 0</pose>
    </model>
  </world>
</sdf>
